Traceback (most recent call last):
  File "C:\Users\Lan\anaconda3\envs\gds2023\lib\site-packages\jupyter_cache\executors\utils.py", line 58, in single_nb_execution
    executenb(
  File "C:\Users\Lan\anaconda3\envs\gds2023\lib\site-packages\nbclient\client.py", line 1204, in execute
    return NotebookClient(nb=nb, resources=resources, km=km, **kwargs).execute()
  File "C:\Users\Lan\anaconda3\envs\gds2023\lib\site-packages\nbclient\util.py", line 84, in wrapped
    return just_run(coro(*args, **kwargs))
  File "C:\Users\Lan\anaconda3\envs\gds2023\lib\site-packages\nbclient\util.py", line 62, in just_run
    return loop.run_until_complete(coro)
  File "C:\Users\Lan\anaconda3\envs\gds2023\lib\asyncio\base_events.py", line 649, in run_until_complete
    return future.result()
  File "C:\Users\Lan\anaconda3\envs\gds2023\lib\site-packages\nbclient\client.py", line 663, in async_execute
    await self.async_execute_cell(
  File "C:\Users\Lan\anaconda3\envs\gds2023\lib\site-packages\nbclient\client.py", line 965, in async_execute_cell
    await self._check_raise_for_error(cell, cell_index, exec_reply)
  File "C:\Users\Lan\anaconda3\envs\gds2023\lib\site-packages\nbclient\client.py", line 862, in _check_raise_for_error
    raise CellExecutionError.from_cell_and_msg(cell, exec_reply_content)
nbclient.exceptions.CellExecutionError: An error occurred while executing the following cell:
------------------
%load_ext jupyter_ai
------------------

[1;31m---------------------------------------------------------------------------[0m
[1;31mModuleNotFoundError[0m                       Traceback (most recent call last)
Cell [1;32mIn[38], line 1[0m
[1;32m----> 1[0m [43mget_ipython[49m[43m([49m[43m)[49m[38;5;241;43m.[39;49m[43mrun_line_magic[49m[43m([49m[38;5;124;43m'[39;49m[38;5;124;43mload_ext[39;49m[38;5;124;43m'[39;49m[43m,[49m[43m [49m[38;5;124;43m'[39;49m[38;5;124;43mjupyter_ai[39;49m[38;5;124;43m'[39;49m[43m)[49m

File [1;32m~\anaconda3\envs\gds2023\lib\site-packages\IPython\core\interactiveshell.py:2414[0m, in [0;36mInteractiveShell.run_line_magic[1;34m(self, magic_name, line, _stack_depth)[0m
[0;32m   2412[0m     kwargs[[38;5;124m'[39m[38;5;124mlocal_ns[39m[38;5;124m'[39m] [38;5;241m=[39m [38;5;28mself[39m[38;5;241m.[39mget_local_scope(stack_depth)
[0;32m   2413[0m [38;5;28;01mwith[39;00m [38;5;28mself[39m[38;5;241m.[39mbuiltin_trap:
[1;32m-> 2414[0m     result [38;5;241m=[39m fn([38;5;241m*[39margs, [38;5;241m*[39m[38;5;241m*[39mkwargs)
[0;32m   2416[0m [38;5;66;03m# The code below prevents the output from being displayed[39;00m
[0;32m   2417[0m [38;5;66;03m# when using magics with decodator @output_can_be_silenced[39;00m
[0;32m   2418[0m [38;5;66;03m# when the last Python token in the expression is a ';'.[39;00m
[0;32m   2419[0m [38;5;28;01mif[39;00m [38;5;28mgetattr[39m(fn, magic[38;5;241m.[39mMAGIC_OUTPUT_CAN_BE_SILENCED, [38;5;28;01mFalse[39;00m):

File [1;32m~\anaconda3\envs\gds2023\lib\site-packages\IPython\core\magics\extension.py:33[0m, in [0;36mExtensionMagics.load_ext[1;34m(self, module_str)[0m
[0;32m     31[0m [38;5;28;01mif[39;00m [38;5;129;01mnot[39;00m module_str:
[0;32m     32[0m     [38;5;28;01mraise[39;00m UsageError([38;5;124m'[39m[38;5;124mMissing module name.[39m[38;5;124m'[39m)
[1;32m---> 33[0m res [38;5;241m=[39m [38;5;28;43mself[39;49m[38;5;241;43m.[39;49m[43mshell[49m[38;5;241;43m.[39;49m[43mextension_manager[49m[38;5;241;43m.[39;49m[43mload_extension[49m[43m([49m[43mmodule_str[49m[43m)[49m
[0;32m     35[0m [38;5;28;01mif[39;00m res [38;5;241m==[39m [38;5;124m'[39m[38;5;124malready loaded[39m[38;5;124m'[39m:
[0;32m     36[0m     [38;5;28mprint[39m([38;5;124m"[39m[38;5;124mThe [39m[38;5;132;01m%s[39;00m[38;5;124m extension is already loaded. To reload it, use:[39m[38;5;124m"[39m [38;5;241m%[39m module_str)

File [1;32m~\anaconda3\envs\gds2023\lib\site-packages\IPython\core\extensions.py:76[0m, in [0;36mExtensionManager.load_extension[1;34m(self, module_str)[0m
[0;32m     69[0m [38;5;250m[39m[38;5;124;03m"""Load an IPython extension by its module name.[39;00m
[0;32m     70[0m 
[0;32m     71[0m [38;5;124;03mReturns the string "already loaded" if the extension is already loaded,[39;00m
[0;32m     72[0m [38;5;124;03m"no load function" if the module doesn't have a load_ipython_extension[39;00m
[0;32m     73[0m [38;5;124;03mfunction, or None if it succeeded.[39;00m
[0;32m     74[0m [38;5;124;03m"""[39;00m
[0;32m     75[0m [38;5;28;01mtry[39;00m:
[1;32m---> 76[0m     [38;5;28;01mreturn[39;00m [38;5;28;43mself[39;49m[38;5;241;43m.[39;49m[43m_load_extension[49m[43m([49m[43mmodule_str[49m[43m)[49m
[0;32m     77[0m [38;5;28;01mexcept[39;00m [38;5;167;01mModuleNotFoundError[39;00m:
[0;32m     78[0m     [38;5;28;01mif[39;00m module_str [38;5;129;01min[39;00m BUILTINS_EXTS:

File [1;32m~\anaconda3\envs\gds2023\lib\site-packages\IPython\core\extensions.py:91[0m, in [0;36mExtensionManager._load_extension[1;34m(self, module_str)[0m
[0;32m     89[0m [38;5;28;01mwith[39;00m [38;5;28mself[39m[38;5;241m.[39mshell[38;5;241m.[39mbuiltin_trap:
[0;32m     90[0m     [38;5;28;01mif[39;00m module_str [38;5;129;01mnot[39;00m [38;5;129;01min[39;00m sys[38;5;241m.[39mmodules:
[1;32m---> 91[0m         mod [38;5;241m=[39m [43mimport_module[49m[43m([49m[43mmodule_str[49m[43m)[49m
[0;32m     92[0m     mod [38;5;241m=[39m sys[38;5;241m.[39mmodules[module_str]
[0;32m     93[0m     [38;5;28;01mif[39;00m [38;5;28mself[39m[38;5;241m.[39m_call_load_ipython_extension(mod):

File [1;32m~\anaconda3\envs\gds2023\lib\importlib\__init__.py:126[0m, in [0;36mimport_module[1;34m(name, package)[0m
[0;32m    124[0m             [38;5;28;01mbreak[39;00m
[0;32m    125[0m         level [38;5;241m+[39m[38;5;241m=[39m [38;5;241m1[39m
[1;32m--> 126[0m [38;5;28;01mreturn[39;00m [43m_bootstrap[49m[38;5;241;43m.[39;49m[43m_gcd_import[49m[43m([49m[43mname[49m[43m[[49m[43mlevel[49m[43m:[49m[43m][49m[43m,[49m[43m [49m[43mpackage[49m[43m,[49m[43m [49m[43mlevel[49m[43m)[49m

File [1;32m<frozen importlib._bootstrap>:1050[0m, in [0;36m_gcd_import[1;34m(name, package, level)[0m

File [1;32m<frozen importlib._bootstrap>:1027[0m, in [0;36m_find_and_load[1;34m(name, import_)[0m

File [1;32m<frozen importlib._bootstrap>:1004[0m, in [0;36m_find_and_load_unlocked[1;34m(name, import_)[0m

[1;31mModuleNotFoundError[0m: No module named 'jupyter_ai'
ModuleNotFoundError: No module named 'jupyter_ai'

